<?xml version="1.0"?>
<robot name="b1z1_description">
  <material name="black">
    <color rgba="0.0 0.0 0.0 1.0" />
  </material>
  <material name="blue">
    <color rgba="0.0 0.0 0.8 1.0" />
  </material>
  <material name="green">
    <color rgba="0.0 0.8 0.0 1.0" />
  </material>
  <material name="grey">
    <color rgba="0.2 0.2 0.2 1.0" />
  </material>
  <material name="silver">
    <color rgba="0.9137254901960784 0.9137254901960784 0.8470588235294118 1.0" />
  </material>
  <material name="orange">
    <!-- <color rgba="1.0 0.4235294117647059 0.0392156862745098 1.0"/> -->
    <color rgba="0.12 0.15 0.2 1.0" />
  </material>
  <material name="brown">
    <color rgba="0.8705882352941177 0.8117647058823529 0.7647058823529411 1.0" />
  </material>
  <material name="red">
    <color rgba="0.8 0.0 0.0 1.0" />
  </material>
  <material name="white">
    <color rgba="1.0 1.0 1.0 1.0" />
  </material>


  <!-- Start of B1 Links and Joints -->
  <link name="base">
    <visual>
      <origin rpy="0 0 0" xyz="0 0 0" />
      <geometry>
        <box size="0.001 0.001 0.001" />
      </geometry>
    </visual>
  </link>
  <joint name="floating_base" type="fixed" dont_collapse="true">
    <origin rpy="0 0 0" xyz="0 0 0" />
    <parent link="base" />
    <child link="trunk" />
  </joint>
  <link name="trunk">
    <visual>
      <origin rpy="0 0 0" xyz="0 0 0" />
      <geometry>
        <mesh filename="../meshes/trunk.dae"
          scale="1 1 1" />
      </geometry>
      <material name="orange" />
    </visual>
    <collision>
      <origin rpy="0 0 0" xyz="0 0 0" />
      <geometry>
        <box size="0.647 0.3 0.15" />
      </geometry>
    </collision>
    <!-- <collision>
            <origin rpy="0 0 0" xyz="0 0 0"/>
            <geometry>
                <mesh filename="../meshes/trunk.dae" scale="1 1
    1"/>
            </geometry>
        </collision> -->
    <inertial>
      <origin rpy="0 0 0" xyz="0.008987 0.002243 0.003013" />
      <mass value="25" />
      <inertia ixx="0.183142146" ixy="-0.001379002" ixz="-0.027956055" iyy="0.756327752"
        iyz="0.000193774" izz="0.783777558" />
    </inertial>
  </link>
  <joint name="imu_joint" type="fixed">
    <parent link="trunk" />
    <child link="imu_link" />
    <origin rpy="0 0 0" xyz="0 0 0" />
  </joint>
  <link name="imu_link">
    <inertial>
      <mass value="0.001" />
      <origin rpy="0 0 0" xyz="0 0 0" />
      <inertia ixx="0.0001" ixy="0" ixz="0" iyy="0.000001" iyz="0" izz="0.0001" />
    </inertial>
    <visual>
      <origin rpy="0 0 0" xyz="0 0 0" />
      <geometry>
        <box size="0.001 0.001 0.001" />
      </geometry>
      <material name="red" />
    </visual>
    <!-- <collision>
      <origin rpy="0 0 0" xyz="0 0 0"/>
      <geometry>
        <box size=".001 .001 .001"/>
      </geometry>
    </collision> -->
  </link>
  <joint name="FR_hip_joint" type="revolute">
    <origin rpy="0 0 0" xyz="0.3455 -0.072 0" />
    <parent link="trunk" />
    <child link="FR_hip" />
    <axis xyz="1 0 0" />
    <dynamics damping="0" friction="0" />
    <limit effort="91.0035" lower="-0.75" upper="0.75" velocity="19.69" />
  </joint>
  <link name="FR_hip">
    <visual>
      <origin rpy="3.141592653589793 0 0" xyz="0 0 0" />
      <geometry>
        <mesh filename="../meshes/hip.dae"
          scale="1 1 1" />
      </geometry>
      <material name="orange" />
    </visual>
    <!-- <collision>
      <origin rpy="1.5707963267948966 0 0" xyz="0 -0.12675 0"/>
      <geometry>
        <cylinder length="0.04" radius="0.09"/>
      </geometry>
    </collision> -->
    <inertial>
      <origin rpy="0 0 0" xyz="-0.020298 -0.009758 0.000109" />
      <mass value="2.1" />
      <inertia ixx="0.00406608" ixy="0.000288071" ixz="-4.371e-06" iyy="0.008775259"
        iyz="-1.811e-06" izz="0.006060348" />
    </inertial>
  </link>
  <joint name="FR_thigh_joint" type="revolute">
    <origin rpy="0 0 0" xyz="0 -0.12675 0" />
    <parent link="FR_hip" />
    <child link="FR_thigh" />
    <axis xyz="0 1 0" />
    <dynamics damping="0" friction="0" />
    <limit effort="93.33" lower="-1.0" upper="3.5" velocity="23.32" />
  </joint>
  <link name="FR_thigh">
    <visual>
      <origin rpy="0 0 0" xyz="0 0 0" />
      <geometry>
        <mesh
          filename="../meshes/thigh_mirror.dae"
          scale="1 1 1" />
      </geometry>
      <material name="orange" />
    </visual>
    <collision>
      <origin rpy="0 1.5707963267948966 0" xyz="0 0 -0.175" />
      <geometry>
        <box size="0.35 0.05 0.08" />
      </geometry>
    </collision>
    <inertial>
      <origin rpy="0 0 0" xyz="-0.000235 0.028704 -0.054169" />
      <mass value="3.934" />
      <inertia ixx="0.044459086" ixy="-0.000128738" ixz="-0.002343913" iyy="0.046023457"
        iyz="-0.006032996" izz="0.008696078" />
    </inertial>
  </link>
  <joint name="FR_calf_joint" type="revolute">
    <origin rpy="0 0 0" xyz="0 0 -0.35" />
    <parent link="FR_thigh" />
    <child link="FR_calf" />
    <axis xyz="0 1 0" />
    <dynamics damping="0" friction="0" />
    <limit effort="140" lower="-2.6" upper="-0.6" velocity="15.55" />
  </joint>
  <link name="FR_calf">
    <visual>
      <origin rpy="0 0 0" xyz="0 0 0" />
      <geometry>
        <mesh filename="../meshes/calf.dae"
          scale="1 1 1" />
      </geometry>
      <material name="orange" />
    </visual>
    <collision>
      <origin rpy="0 1.5707963267948966 0" xyz="0 0 -0.175" />
      <geometry>
        <box size="0.35 0.04 0.05" />
      </geometry>
    </collision>
    <inertial>
      <origin rpy="0 0 0" xyz="0.005237 0.0 -0.202805" />
      <mass value="0.857" />
      <inertia ixx="0.015011003" ixy="5.2e-08" ixz="0.000250042" iyy="0.015159462" iyz="4.61e-07"
        izz="0.000375749" />
    </inertial>
  </link>
  <joint name="FR_foot_fixed" type="fixed" dont_collapse="true">
    <origin rpy="0 0 0" xyz="0 0 -0.35" />
    <parent link="FR_calf" />
    <child link="FR_foot" />
  </joint>
  <link name="FR_foot">
    <visual>
      <origin rpy="0 0 0" xyz="0 0 0" />
      <geometry>
        <sphere radius="0.03" />
      </geometry>
      <material name="green" />
    </visual>
    <collision>
      <origin rpy="0 0 0" xyz="0 0 0" />
      <geometry>
        <sphere radius="0.04" />
      </geometry>
    </collision>
    <inertial>
      <mass value="0.05" />
      <inertia ixx="3.2000000000000005e-05" ixy="0.0" ixz="0.0" iyy="3.2000000000000005e-05"
        iyz="0.0" izz="3.2000000000000005e-05" />
    </inertial>
  </link>
  <joint name="FL_hip_joint" type="revolute">
    <origin rpy="0 0 0" xyz="0.3455 0.072 0" />
    <parent link="trunk" />
    <child link="FL_hip" />
    <axis xyz="1 0 0" />
    <dynamics damping="0" friction="0" />
    <limit effort="91.0035" lower="-0.75" upper="0.75" velocity="19.69" />
  </joint>
  <link name="FL_hip">
    <visual>
      <origin rpy="0 0 0" xyz="0 0 0" />
      <geometry>
        <mesh filename="../meshes/hip.dae"
          scale="1 1 1" />
      </geometry>
      <material name="orange" />
    </visual>
    <!-- <collision>
      <origin rpy="1.5707963267948966 0 0" xyz="0 0.12675 0"/>
      <geometry>
        <cylinder length="0.04" radius="0.09"/>
      </geometry>
    </collision> -->
    <inertial>
      <origin rpy="0 0 0" xyz="-0.020298 0.009758 0.000109" />
      <mass value="2.1" />
      <inertia ixx="0.00406608" ixy="-0.000288071" ixz="-4.371e-06" iyy="0.008775259"
        iyz="1.811e-06" izz="0.006060348" />
    </inertial>
  </link>
  <joint name="FL_thigh_joint" type="revolute">
    <origin rpy="0 0 0" xyz="0 0.12675 0" />
    <parent link="FL_hip" />
    <child link="FL_thigh" />
    <axis xyz="0 1 0" />
    <dynamics damping="0" friction="0" />
    <limit effort="93.33" lower="-1.0" upper="3.5" velocity="23.32" />
  </joint>
  <link name="FL_thigh">
    <visual>
      <origin rpy="0 0 0" xyz="0 0 0" />
      <geometry>
        <mesh filename="../meshes/thigh.dae"
          scale="1 1 1" />
      </geometry>
      <material name="orange" />
    </visual>
    <collision>
      <origin rpy="0 1.5707963267948966 0" xyz="0 0 -0.175" />
      <geometry>
        <box size="0.35 0.05 0.08" />
      </geometry>
    </collision>
    <inertial>
      <origin rpy="0 0 0" xyz="-0.000235 -0.028704 -0.054169" />
      <mass value="3.934" />
      <inertia ixx="0.044459086" ixy="0.000128738" ixz="-0.002343913" iyy="0.046023457"
        iyz="0.006032996" izz="0.008696078" />
    </inertial>
  </link>
  <joint name="FL_calf_joint" type="revolute">
    <origin rpy="0 0 0" xyz="0 0 -0.35" />
    <parent link="FL_thigh" />
    <child link="FL_calf" />
    <axis xyz="0 1 0" />
    <dynamics damping="0" friction="0" />
    <limit effort="140" lower="-2.6" upper="-0.6" velocity="15.55" />
  </joint>
  <link name="FL_calf">
    <visual>
      <origin rpy="0 0 0" xyz="0 0 0" />
      <geometry>
        <mesh filename="../meshes/calf.dae"
          scale="1 1 1" />
      </geometry>
      <material name="orange" />
    </visual>
    <collision>
      <origin rpy="0 1.5707963267948966 0" xyz="0 0 -0.175" />
      <geometry>
        <box size="0.35 0.04 0.05" />
      </geometry>
    </collision>
    <inertial>
      <origin rpy="0 0 0" xyz="0.005237 0.0 -0.202805" />
      <mass value="0.857" />
      <inertia ixx="0.015011003" ixy="5.2e-08" ixz="0.000250042" iyy="0.015159462" iyz="4.61e-07"
        izz="0.000375749" />
    </inertial>
  </link>
  <joint name="FL_foot_fixed" type="fixed" dont_collapse="true">
    <origin rpy="0 0 0" xyz="0 0 -0.35" />
    <parent link="FL_calf" />
    <child link="FL_foot" />
  </joint>
  <link name="FL_foot">
    <visual>
      <origin rpy="0 0 0" xyz="0 0 0" />
      <geometry>
        <sphere radius="0.03" />
      </geometry>
      <material name="green" />
    </visual>
    <collision>
      <origin rpy="0 0 0" xyz="0 0 0" />
      <geometry>
        <sphere radius="0.04" />
      </geometry>
    </collision>
    <inertial>
      <mass value="0.05" />
      <inertia ixx="3.2000000000000005e-05" ixy="0.0" ixz="0.0" iyy="3.2000000000000005e-05"
        iyz="0.0" izz="3.2000000000000005e-05" />
    </inertial>
  </link>
  <joint name="RR_hip_joint" type="revolute">
    <origin rpy="0 0 0" xyz="-0.3455 -0.072 0" />
    <parent link="trunk" />
    <child link="RR_hip" />
    <axis xyz="1 0 0" />
    <dynamics damping="0" friction="0" />
    <limit effort="91.0035" lower="-0.75" upper="0.75" velocity="19.69" />
  </joint>
  <link name="RR_hip">
    <visual>
      <origin rpy="3.141592653589793 3.141592653589793 0" xyz="0 0 0" />
      <geometry>
        <mesh filename="../meshes/hip.dae"
          scale="1 1 1" />
      </geometry>
      <material name="orange" />
    </visual>
    <!-- <collision>
      <origin rpy="1.5707963267948966 0 0" xyz="0 -0.12675 0"/>
      <geometry>
        <cylinder length="0.04" radius="0.09"/>
      </geometry>
    </collision> -->
    <inertial>
      <origin rpy="0 0 0" xyz="0.020298 -0.009758 0.000109" />
      <mass value="2.1" />
      <inertia ixx="0.00406608" ixy="-0.000288071" ixz="4.371e-06" iyy="0.008775259"
        iyz="-1.811e-06" izz="0.006060348" />
    </inertial>
  </link>
  <joint name="RR_thigh_joint" type="revolute">
    <origin rpy="0 0 0" xyz="0 -0.12675 0" />
    <parent link="RR_hip" />
    <child link="RR_thigh" />
    <axis xyz="0 1 0" />
    <dynamics damping="0" friction="0" />
    <limit effort="93.33" lower="-1.0" upper="3.5" velocity="23.32" />
  </joint>
  <link name="RR_thigh">
    <visual>
      <origin rpy="0 0 0" xyz="0 0 0" />
      <geometry>
        <mesh
          filename="../meshes/thigh_mirror.dae"
          scale="1 1 1" />
      </geometry>
      <material name="orange" />
    </visual>
    <collision>
      <origin rpy="0 1.5707963267948966 0" xyz="0 0 -0.175" />
      <geometry>
        <box size="0.35 0.05 0.08" />
      </geometry>
    </collision>
    <inertial>
      <origin rpy="0 0 0" xyz="-0.000235 0.028704 -0.054169" />
      <mass value="3.934" />
      <inertia ixx="0.044459086" ixy="-0.000128738" ixz="-0.002343913" iyy="0.046023457"
        iyz="-0.006032996" izz="0.008696078" />
    </inertial>
  </link>
  <joint name="RR_calf_joint" type="revolute">
    <origin rpy="0 0 0" xyz="0 0 -0.35" />
    <parent link="RR_thigh" />
    <child link="RR_calf" />
    <axis xyz="0 1 0" />
    <dynamics damping="0" friction="0" />
    <limit effort="140" lower="-2.6" upper="-0.6" velocity="15.55" />
  </joint>
  <link name="RR_calf">
    <visual>
      <origin rpy="0 0 0" xyz="0 0 0" />
      <geometry>
        <mesh filename="../meshes/calf.dae"
          scale="1 1 1" />
      </geometry>
      <material name="orange" />
    </visual>
    <collision>
      <origin rpy="0 1.5707963267948966 0" xyz="0 0 -0.175" />
      <geometry>
        <box size="0.35 0.04 0.05" />
      </geometry>
    </collision>
    <inertial>
      <origin rpy="0 0 0" xyz="0.005237 0.0 -0.202805" />
      <mass value="0.857" />
      <inertia ixx="0.015011003" ixy="5.2e-08" ixz="0.000250042" iyy="0.015159462" iyz="4.61e-07"
        izz="0.000375749" />
    </inertial>
  </link>
  <joint name="RR_foot_fixed" type="fixed" dont_collapse="true">
    <origin rpy="0 0 0" xyz="0 0 -0.35" />
    <parent link="RR_calf" />
    <child link="RR_foot" />
  </joint>
  <link name="RR_foot">
    <visual>
      <origin rpy="0 0 0" xyz="0 0 0" />
      <geometry>
        <sphere radius="0.03" />
      </geometry>
      <material name="green" />
    </visual>
    <collision>
      <origin rpy="0 0 0" xyz="0 0 0" />
      <geometry>
        <sphere radius="0.04" />
      </geometry>
    </collision>
    <inertial>
      <mass value="0.05" />
      <inertia ixx="3.2000000000000005e-05" ixy="0.0" ixz="0.0" iyy="3.2000000000000005e-05"
        iyz="0.0" izz="3.2000000000000005e-05" />
    </inertial>
  </link>
  <joint name="RL_hip_joint" type="revolute">
    <origin rpy="0 0 0" xyz="-0.3455 0.072 0" />
    <parent link="trunk" />
    <child link="RL_hip" />
    <axis xyz="1 0 0" />
    <dynamics damping="0" friction="0" />
    <limit effort="91.0035" lower="-0.75" upper="0.75" velocity="19.69" />
  </joint>
  <link name="RL_hip">
    <visual>
      <origin rpy="0 3.141592653589793 0" xyz="0 0 0" />
      <geometry>
        <mesh filename="../meshes/hip.dae"
          scale="1 1 1" />
      </geometry>
      <material name="orange" />
    </visual>
    <!-- <collision>
      <origin rpy="1.5707963267948966 0 0" xyz="0 0.12675 0"/>
      <geometry>
        <cylinder length="0.04" radius="0.09"/>
      </geometry>
    </collision> -->
    <inertial>
      <origin rpy="0 0 0" xyz="0.020298 0.009758 0.000109" />
      <mass value="2.1" />
      <inertia ixx="0.00406608" ixy="0.000288071" ixz="4.371e-06" iyy="0.008775259" iyz="1.811e-06"
        izz="0.006060348" />
    </inertial>
  </link>
  <joint name="RL_thigh_joint" type="revolute">
    <origin rpy="0 0 0" xyz="0 0.12675 0" />
    <parent link="RL_hip" />
    <child link="RL_thigh" />
    <axis xyz="0 1 0" />
    <dynamics damping="0" friction="0" />
    <limit effort="93.33" lower="-1.0" upper="3.5" velocity="23.32" />
  </joint>
  <link name="RL_thigh">
    <visual>
      <origin rpy="0 0 0" xyz="0 0 0" />
      <geometry>
        <mesh filename="../meshes/thigh.dae"
          scale="1 1 1" />
      </geometry>
      <material name="orange" />
    </visual>
    <collision>
      <origin rpy="0 1.5707963267948966 0" xyz="0 0 -0.175" />
      <geometry>
        <box size="0.35 0.05 0.08" />
      </geometry>
    </collision>
    <inertial>
      <origin rpy="0 0 0" xyz="-0.000235 -0.028704 -0.054169" />
      <mass value="3.934" />
      <inertia ixx="0.044459086" ixy="0.000128738" ixz="-0.002343913" iyy="0.046023457"
        iyz="0.006032996" izz="0.008696078" />
    </inertial>
  </link>
  <joint name="RL_calf_joint" type="revolute">
    <origin rpy="0 0 0" xyz="0 0 -0.35" />
    <parent link="RL_thigh" />
    <child link="RL_calf" />
    <axis xyz="0 1 0" />
    <dynamics damping="0" friction="0" />
    <limit effort="140" lower="-2.6" upper="-0.6" velocity="15.55" />
  </joint>
  <link name="RL_calf">
    <visual>
      <origin rpy="0 0 0" xyz="0 0 0" />
      <geometry>
        <mesh filename="../meshes/calf.dae"
          scale="1 1 1" />
      </geometry>
      <material name="orange" />
    </visual>
    <collision>
      <origin rpy="0 1.5707963267948966 0" xyz="0 0 -0.175" />
      <geometry>
        <box size="0.35 0.04 0.05" />
      </geometry>
    </collision>
    <inertial>
      <origin rpy="0 0 0" xyz="0.005237 0.0 -0.202805" />
      <mass value="0.857" />
      <inertia ixx="0.015011003" ixy="5.2e-08" ixz="0.000250042" iyy="0.015159462" iyz="4.61e-07"
        izz="0.000375749" />
    </inertial>
  </link>
  <joint name="RL_foot_fixed" type="fixed" dont_collapse="true">
    <origin rpy="0 0 0" xyz="0 0 -0.35" />
    <parent link="RL_calf" />
    <child link="RL_foot" />
  </joint>
  <link name="RL_foot">
    <visual>
      <origin rpy="0 0 0" xyz="0 0 0" />
      <geometry>
        <sphere radius="0.03" />
      </geometry>
      <material name="green" />
    </visual>
    <collision>
      <origin rpy="0 0 0" xyz="0 0 0" />
      <geometry>
        <sphere radius="0.04" />
      </geometry>
    </collision>
    <inertial>
      <mass value="0.05" />
      <inertia ixx="3.2000000000000005e-05" ixy="0.0" ixz="0.0" iyy="3.2000000000000005e-05"
        iyz="0.0" izz="3.2000000000000005e-05" />
    </inertial>
  </link>


  <!-- Start of Z1 Links and Joints -->
  <joint name="base_static_joint" type="fixed">
    <origin rpy="0 0 0" xyz="0.3 0 0.09>>" />
    <parent link="base" />
    <child link="link00" />
  </joint>
  <link name="link00">
    <visual>
      <origin rpy="1.5707963267948966 0 0" xyz="0 0 0" />
      <geometry>
        <mesh filename="../meshes/z1_Link00.dae"
          scale="1 1 1" />
      </geometry>
    </visual>
    <collision>
      <geometry>
        <cylinder length="0.03" radius="0.0325" />
      </geometry>
      <origin rpy="0 0 0" xyz="0 0 0.0255" />
    </collision>
    <inertial>
      <origin rpy="1.5707963267948966 0 0" xyz="-0.00334984 -0.00013615 0.02495843" />
      <mass value="0.47247481" />
      <inertia ixx="0.00037937" ixy="3.5e-07" ixz="1.037e-05" iyy="0.00041521" iyz="9.9e-07"
        izz="0.00053066" />
    </inertial>
  </link>
  <joint name="z1_waist" type="revolute">
    <origin rpy="0 0 0" xyz="0 0 0.0585" />
    <parent link="link00" />
    <child link="link01" />
    <axis xyz="0 0 1" />
    <dynamics damping="1.0" friction="1.0" />
    <limit effort="30.0" lower="-2.6179938779914944" upper="2.6179938779914944" velocity="10" />
  </joint>
  <link name="link01">
    <visual>
      <origin rpy="1.5707963267948966 0 0" xyz="0 0 0" />
      <geometry>
        <mesh filename="../meshes/z1_Link01.dae"
          scale="1 1 1" />
      </geometry>
    </visual>
    <!-- <collision>
            <geometry>
                <cylinder length="${2*motor_height}" radius="${motor_diameter}"/>
            </geometry>
            <origin rpy="0 0 0" xyz="0 0 0"/>
        </collision> -->
    <inertial>
      <origin rpy="1.5707963267948966 0 0" xyz="2.47e-06 -0.00025198 0.02317169" />
      <mass value="0.67332551" />
      <inertia ixx="0.00128328" ixy="6e-08" ixz="4e-07" iyy="0.00071931" iyz="-5e-07"
        izz="0.00083936" />
    </inertial>
  </link>
  <joint name="z1_shoulder" type="revolute">
    <origin rpy="0 0 0" xyz="0 0 0.045" />
    <parent link="link01" />
    <child link="link02" />
    <axis xyz="0 1 0" />
    <dynamics damping="2.0" friction="2.0" />
    <limit effort="60.0" lower="0.0" upper="3.141592653589793" velocity="10" />
  </joint>
  <link name="link02">
    <visual>
      <origin rpy="1.5707963267948966 0 0" xyz="0 0 0" />
      <geometry>
        <mesh filename="../meshes/z1_Link02.dae"
          scale="1 1 1" />
      </geometry>
    </visual>
    <collision>
      <geometry>
        <cylinder length="0.102" radius="0.02" />
      </geometry>
      <origin rpy="1.5707963267948966 0 0" xyz="0 0 0" />
    </collision>
    <collision>
      <geometry>
        <cylinder length="0.235" radius="0.0225" />
      </geometry>
      <origin rpy="0 1.5707963267948966 0" xyz="-0.16249999999999998 0 0" />
    </collision>
    <collision>
      <geometry>
        <cylinder length="0.051" radius="0.0325" />
      </geometry>
      <origin rpy="1.5707963267948966 0 0" xyz="-0.35 0 0" />
    </collision>
    <inertial>
      <origin rpy="1.5707963267948966 0 0" xyz="-0.11012601 0.00240029 0.00158266" />
      <mass value="1.19132258" />
      <inertia ixx="0.00102138" ixy="-0.00062358" ixz="-5.13e-06" iyy="0.02429457" iyz="2.1e-06"
        izz="0.02466114" />
    </inertial>
  </link>
  <joint name="z1_elbow" type="revolute">
    <origin rpy="0 0 0" xyz="-0.35 0 0" />
    <parent link="link02" />
    <child link="link03" />
    <axis xyz="0 1 0" />
    <dynamics damping="1.0" friction="1.0" />
    <limit effort="30.0" lower="-4.782202150464463" upper="0.0" velocity="10" />
  </joint>
  <link name="link03">
    <visual>
      <origin rpy="1.5707963267948966 0 0" xyz="0 0 0" />
      <geometry>
        <mesh filename="../meshes/z1_Link03.dae"
          scale="1 1 1" />
      </geometry>
    </visual>
    <collision>
      <geometry>
        <cylinder length="0.116" radius="0.02" />
      </geometry>
      <origin rpy="0 1.5707963267948966 0" xyz="0.128 0 0.055" />
    </collision>
    <collision>
      <geometry>
        <cylinder length="0.059" radius="0.0325" />
      </geometry>
      <origin rpy="0 1.5707963267948966 0" xyz="0.2205 0 0.055" />
    </collision>
    <inertial>
      <origin rpy="1.5707963267948966 0 0" xyz="0.10609208 -0.00541815 0.03476383" />
      <mass value="0.83940874" />
      <inertia ixx="0.00108061" ixy="8.669e-05" ixz="0.00208102" iyy="0.00954238" iyz="1.332e-05"
        izz="0.00886621" />
    </inertial>
  </link>
  <joint name="z1_wrist_angle" type="revolute">
    <origin rpy="0 0 0" xyz="0.218 0 0.057" />
    <parent link="link03" />
    <child link="link04" />
    <axis xyz="0 1 0" />
    <dynamics damping="1.0" friction="1.0" />
    <limit effort="30.0" lower="-1.7453292519943295" upper="1.5707963267948966" velocity="10" />
  </joint>
  <link name="link04">
    <visual>
      <origin rpy="1.5707963267948966 0 0" xyz="0 0 0" />
      <geometry>
        <mesh filename="../meshes/z1_Link04.dae"
          scale="1 1 1" />
      </geometry>
    </visual>
    <collision>
      <geometry>
        <cylinder length="0.073" radius="0.0325" />
      </geometry>
      <origin rpy="1.5707963267948966 0 0" xyz="0.0472 0 0" />
    </collision>
    <inertial>
      <origin rpy="1.5707963267948966 0 0" xyz="0.04366681 0.00364738 -0.00170192" />
      <mass value="0.56404563" />
      <inertia ixx="0.00031576" ixy="-8.13e-05" ixz="-4.091e-05" iyy="0.00092996" iyz="5.96e-06"
        izz="0.00097912" />
    </inertial>
  </link>
  <joint name="z1_forearm_roll" type="revolute">
    <origin rpy="0 0 0" xyz="0.07 0.0 0.0" />
    <parent link="link04" />
    <child link="link05" />
    <axis xyz="0 0 1" />
    <dynamics damping="1.0" friction="1.0" />
    <limit effort="30.0" lower="-1.7278759594743864" upper="1.7278759594743864" velocity="10" />
  </joint>
  <link name="link05">
    <visual>
      <origin rpy="1.5707963267948966 0 0" xyz="0 0 0" />
      <geometry>
        <mesh filename="../meshes/z1_Link05.dae"
          scale="1 1 1" />
      </geometry>
    </visual>
    <inertial>
      <origin rpy="1.5707963267948966 0 0" xyz="0.03121533 0.0 0.00646316" />
      <mass value="0.38938492" />
      <inertia ixx="0.00017605" ixy="-4e-07" ixz="-5.689e-05" iyy="0.00055896" iyz="1.3e-07"
        izz="0.0005386" />
    </inertial>
  </link>
  <joint name="z1_wrist_rotate" type="revolute">
    <origin rpy="0 0 0" xyz="0.0492 0.0 0.0" />
    <parent link="link05" />
    <child link="link06" />
    <axis xyz="1 0 0" />
    <dynamics damping="1.0" friction="1.0" />
    <limit effort="30.0" lower="-2.792526803190927" upper="2.792526803190927" velocity="10" />
  </joint>
  <link name="link06">
    <visual>
      <origin rpy="1.5707963267948966 0 0" xyz="0 0 0" />
      <geometry>
        <mesh filename="../meshes/z1_Link06.dae"
          scale="1 1 1" />
      </geometry>
    </visual>
    <collision>
      <geometry>
        <cylinder length="0.051" radius="0.0325" />
      </geometry>
      <origin rpy="0 1.5707963267948966 0" xyz="0.0255 0 0" />
    </collision>
    <inertial>
      <origin rpy="1.5707963267948966 0 0" xyz="0.0241569 -0.00017355 -0.00143876" />
      <mass value="0.28875807" />
      <inertia ixx="0.00018328" ixy="-1.22e-06" ixz="-5.4e-07" iyy="0.0001475" iyz="-8e-08"
        izz="0.0001468" />
    </inertial>
  </link>
  
  <joint name="z1_gripperStator" type="fixed" >
    <origin rpy="0 0 0" xyz="0.051 0.0 0.0"/>
    <parent link="link06"/>
    <child link="gripperStator"/>
  </joint>
  <link name="gripperStator">
    <visual>
      <origin rpy="1.5707963267948966 0 0" xyz="0 0 0"/>
      <geometry>
        <mesh filename="../meshes/z1_GripperStator.dae" scale="1 1 1"/>
      </geometry>
    </visual>
    <collision>
      <origin rpy="1.5707963267948966 0 0" xyz="0 0 0"/>
      <geometry>
        <mesh filename="../meshes/z1_GripperStator.dae" scale="1 1 1"/>
      </geometry>
    </collision>
    <!-- <collision>
      <geometry>
        <cylinder length="0.051" radius="0.0325"/>
      </geometry>
      <origin rpy="0 0 0" xyz="0 0 0"/>
    </collision> -->
    <inertial>
      <origin rpy="1.5707963267948966 0 0" xyz="0.04764427 -0.00035819 -0.00249162"/>
      <mass value="0.52603655"/>
      <inertia ixx="0.00038683" ixy="3.59e-06" ixz="-7.662e-05" iyy="0.00068614" iyz="-2.09e-06" izz="0.00066293"/>
    </inertial>
  </link>
  <joint name="z1_jointGripper" type="revolute">
    <origin rpy="0 0 0" xyz="0.049 0.0 0"/>
    <parent link="gripperStator"/>
    <child link="gripperMover"/>
    <axis xyz="0 1 0"/>
    <dynamics damping="1.0" friction="1.0"/>
    <limit effort="30.0" lower="-1.5707963267948966" upper="0.0" velocity="10"/>
  </joint>
  <link name="gripperMover">
    <visual>
      <origin rpy="1.5707963267948966 0 0" xyz="0 0 0"/>
      <geometry>
        <mesh filename="../meshes/z1_GripperMover.dae" scale="1 1 1"/>
      </geometry>
    </visual>
    <collision>
      <origin rpy="1.5707963267948966 0 0" xyz="0 0 0"/>
      <geometry>
        <mesh filename="../meshes/z1_GripperMover.dae" scale="1 1 1"/>
      </geometry>
    </collision>
    <inertial>
      <origin rpy="1.5707963267948966 0 0" xyz="0.01320633 0.00476708 0.00380534"/>
      <mass value="0.27621302"/>
      <inertia ixx="0.00017716" ixy="-1.683e-05" ixz="1.786e-05" iyy="0.00026787" iyz="-2.62e-06" izz="0.00035728"/>
    </inertial>
  </link>
  <joint name="ee_gripper" type="fixed" dont_collapse="true">
    <axis xyz="1 0 0"/>
    <origin rpy="0 0 0" xyz="0.135 0 0"/>
    <parent link="gripperStator"/>
    <child link="ee_gripper_link"/>
  </joint>
  <link name="ee_gripper_link">
    <inertial>
      <mass value="0.001"/>
      <inertia ixx="0.001" ixy="0" ixz="0" iyy="0.001" iyz="0" izz="0.001"/>
    </inertial>
  </link>
</robot>